nohup: ignoring input
Unable to init server: Could not connect: Connection refused
Unable to init server: Could not connect: Connection refused

(predict.py:29528): Gdk-CRITICAL **: 19:58:18.337: gdk_cursor_new_for_display: assertion 'GDK_IS_DISPLAY (display)' failed

(predict.py:29528): Gdk-CRITICAL **: 19:58:18.338: gdk_cursor_new_for_display: assertion 'GDK_IS_DISPLAY (display)' failed
2019-04-24 19:58:27.787591: I tensorflow/core/platform/cpu_feature_guard.cc:141] Your CPU supports instructions that this TensorFlow binary was not compiled to use: AVX2 FMA
2019-04-24 19:58:27.974908: I tensorflow/stream_executor/cuda/cuda_gpu_executor.cc:964] successful NUMA node read from SysFS had negative value (-1), but there must be at least one NUMA node, so returning NUMA node zero
2019-04-24 19:58:27.975464: I tensorflow/core/common_runtime/gpu/gpu_device.cc:1432] Found device 0 with properties: 
name: TITAN Xp major: 6 minor: 1 memoryClockRate(GHz): 1.582
pciBusID: 0000:01:00.0
totalMemory: 11,91GiB freeMemory: 11,72GiB
2019-04-24 19:58:27.975480: I tensorflow/core/common_runtime/gpu/gpu_device.cc:1511] Adding visible gpu devices: 0
2019-04-24 19:58:32.239074: I tensorflow/core/common_runtime/gpu/gpu_device.cc:982] Device interconnect StreamExecutor with strength 1 edge matrix:
2019-04-24 19:58:32.239166: I tensorflow/core/common_runtime/gpu/gpu_device.cc:988]      0 
2019-04-24 19:58:32.239191: I tensorflow/core/common_runtime/gpu/gpu_device.cc:1001] 0:   N 
2019-04-24 19:58:32.240353: I tensorflow/core/common_runtime/gpu/gpu_device.cc:1115] Created TensorFlow device (/job:localhost/replica:0/task:0/device:GPU:0 with 11343 MB memory) -> physical GPU (device: 0, name: TITAN Xp, pci bus id: 0000:01:00.0, compute capability: 6.1)
Using TensorFlow backend.
tf.estimator package not installed.
tf.estimator package not installed.
20
Step:  17 2768 2428 2767 2428
MAX time seen 361.0
Traceback (most recent call last):
  File "predict.py", line 138, in <module>
    predict_all(step, 'v')
  File "predict.py", line 117, in predict_all
    report = classification_report(y_true, y_pred, target_names = target_labels, labels = labels)
  File "/usr/local/lib/python3.6/dist-packages/sklearn/metrics/classification.py", line 1524, in classification_report
    y_type, y_true, y_pred = _check_targets(y_true, y_pred)
  File "/usr/local/lib/python3.6/dist-packages/sklearn/metrics/classification.py", line 71, in _check_targets
    check_consistent_length(y_true, y_pred)
  File "/usr/local/lib/python3.6/dist-packages/sklearn/utils/validation.py", line 235, in check_consistent_length
    " samples: %r" % [int(l) for l in lengths])
ValueError: Found input variables with inconsistent numbers of samples: [6718276, 5895184]
